Workbook

Sheet Dashboard
B2: Business Analytics Dashboard — FY2025 Sales Performance
B3: Interactive sales overview across Region, Category and Time (sample/dummy data)
I4: Pivot-style Summary Tables (feed the charts below)
B5: FILTERS | E5: Change the dropdown values above (Region / Category / Month) — every KPI, table and chart recalculates instantly, like a slicer.
B6: Region | C6: All | I6: Month | J6: Revenue
B7: Category | C7: All | I7: Jan | J7: =IFERROR(SUMIFS('Sales Data'!$H$2:$H$61,'Sales Data'!$C$2:$C$61,IF($C$6="All","*",$C$6),'Sales Data'!$D$2:$D$61,IF($C$7="All","*",$C$7),'Sales Data'!$L$2:$L$61,"Jan"),0) -> 131551
B8: Month | C8: All | I8: Feb | J8: =IFERROR(SUMIFS('Sales Data'!$H$2:$H$61,'Sales Data'!$C$2:$C$61,IF($C$6="All","*",$C$6),'Sales Data'!$D$2:$D$61,IF($C$7="All","*",$C$7),'Sales Data'!$L$2:$L$61,"Feb"),0) -> 153971
I9: Mar | J9: =IFERROR(SUMIFS('Sales Data'!$H$2:$H$61,'Sales Data'!$C$2:$C$61,IF($C$6="All","*",$C$6),'Sales Data'!$D$2:$D$61,IF($C$7="All","*",$C$7),'Sales Data'!$L$2:$L$61,"Mar"),0) -> 110719
B10: Total Revenue | D10: Total Profit | F10: Margin % | I10: Apr | J10: =IFERROR(SUMIFS('Sales Data'!$H$2:$H$61,'Sales Data'!$C$2:$C$61,IF($C$6="All","*",$C$6),'Sales Data'!$D$2:$D$61,IF($C$7="All","*",$C$7),'Sales Data'!$L$2:$L$61,"Apr"),0) -> 123532
B11: =IFERROR(SUMIFS('Sales Data'!$H$2:$H$61,'Sales Data'!$C$2:$C$61,IF($C$6="All","*",$C$6),'Sales Data'!$D$2:$D$61,IF($C$7="All","*",$C$7),'Sales Data'!$L$2:$L$61,IF($C$8="All","*",$C$8)),0) -> 1738768 | D11: =IFERROR(SUMIFS('Sales Data'!$J$2:$J$61,'Sales Data'!$C$2:$C$61,IF($C$6="All","*",$C$6),'Sales Data'!$D$2:$D$61,IF($C$7="All","*",$C$7),'Sales Data'!$L$2:$L$61,IF($C$8="All","*",$C$8)),0) -> 635987 | F11: =IFERROR(D11/B11,0) -> 0.36576875 | I11: May | J11: =IFERROR(SUMIFS('Sales Data'!$H$2:$H$61,'Sales Data'!$C$2:$C$61,IF($C$6="All","*",$C$6),'Sales Data'!$D$2:$D$61,IF($C$7="All","*",$C$7),'Sales Data'!$L$2:$L$61,"May"),0) -> 187091
I12: Jun | J12: =IFERROR(SUMIFS('Sales Data'!$H$2:$H$61,'Sales Data'!$C$2:$C$61,IF($C$6="All","*",$C$6),'Sales Data'!$D$2:$D$61,IF($C$7="All","*",$C$7),'Sales Data'!$L$2:$L$61,"Jun"),0) -> 70735
B13: Total Orders | D13: Total Units | F13: Avg Order Value | I13: Jul | J13: =IFERROR(SUMIFS('Sales Data'!$H$2:$H$61,'Sales Data'!$C$2:$C$61,IF($C$6="All","*",$C$6),'Sales Data'!$D$2:$D$61,IF($C$7="All","*",$C$7),'Sales Data'!$L$2:$L$61,"Jul"),0) -> 246479
B14: =IFERROR(COUNTIFS('Sales Data'!$C$2:$C$61,IF($C$6="All","*",$C$6),'Sales Data'!$D$2:$D$61,IF($C$7="All","*",$C$7),'Sales Data'!$L$2:$L$61,IF($C$8="All","*",$C$8)),0) -> 60 | D14: =IFERROR(SUMIFS('Sales Data'!$F$2:$F$61,'Sales Data'!$C$2:$C$61,IF($C$6="All","*",$C$6),'Sales Data'!$D$2:$D$61,IF($C$7="All","*",$C$7),'Sales Data'!$L$2:$L$61,IF($C$8="All","*",$C$8)),0) -> 832 | F14: =IFERROR(B11/B14,0) -> 28979.467 | I14: Aug | J14: =IFERROR(SUMIFS('Sales Data'!$H$2:$H$61,'Sales Data'!$C$2:$C$61,IF($C$6="All","*",$C$6),'Sales Data'!$D$2:$D$61,IF($C$7="All","*",$C$7),'Sales Data'!$L$2:$L$61,"Aug"),0) -> 121059
I15: Sep | J15: =IFERROR(SUMIFS('Sales Data'!$H$2:$H$61,'Sales Data'!$C$2:$C$61,IF($C$6="All","*",$C$6),'Sales Data'!$D$2:$D$61,IF($C$7="All","*",$C$7),'Sales Data'!$L$2:$L$61,"Sep"),0) -> 101939
I16: Oct | J16: =IFERROR(SUMIFS('Sales Data'!$H$2:$H$61,'Sales Data'!$C$2:$C$61,IF($C$6="All","*",$C$6),'Sales Data'!$D$2:$D$61,IF($C$7="All","*",$C$7),'Sales Data'!$L$2:$L$61,"Oct"),0) -> 232425
I17: Nov | J17: =IFERROR(SUMIFS('Sales Data'!$H$2:$H$61,'Sales Data'!$C$2:$C$61,IF($C$6="All","*",$C$6),'Sales Data'!$D$2:$D$61,IF($C$7="All","*",$C$7),'Sales Data'!$L$2:$L$61,"Nov"),0) -> 120236
I18: Dec | J18: =IFERROR(SUMIFS('Sales Data'!$H$2:$H$61,'Sales Data'!$C$2:$C$61,IF($C$6="All","*",$C$6),'Sales Data'!$D$2:$D$61,IF($C$7="All","*",$C$7),'Sales Data'!$L$2:$L$61,"Dec"),0) -> 139031
I20: Region | J20: Revenue
I21: North | J21: =IFERROR(SUMIFS('Sales Data'!$H$2:$H$61,'Sales Data'!$C$2:$C$61,"North",'Sales Data'!$D$2:$D$61,IF($C$7="All","*",$C$7),'Sales Data'!$L$2:$L$61,IF($C$8="All","*",$C$8)),0) -> 351250
I22: South | J22: =IFERROR(SUMIFS('Sales Data'!$H$2:$H$61,'Sales Data'!$C$2:$C$61,"South",'Sales Data'!$D$2:$D$61,IF($C$7="All","*",$C$7),'Sales Data'!$L$2:$L$61,IF($C$8="All","*",$C$8)),0) -> 290027
I23: East | J23: =IFERROR(SUMIFS('Sales Data'!$H$2:$H$61,'Sales Data'!$C$2:$C$61,"East",'Sales Data'!$D$2:$D$61,IF($C$7="All","*",$C$7),'Sales Data'!$L$2:$L$61,IF($C$8="All","*",$C$8)),0) -> 620879
I24: West | J24: =IFERROR(SUMIFS('Sales Data'!$H$2:$H$61,'Sales Data'!$C$2:$C$61,"West",'Sales Data'!$D$2:$D$61,IF($C$7="All","*",$C$7),'Sales Data'!$L$2:$L$61,IF($C$8="All","*",$C$8)),0) -> 476612
I26: Category | J26: Revenue
I27: Electronics | J27: =IFERROR(SUMIFS('Sales Data'!$H$2:$H$61,'Sales Data'!$C$2:$C$61,IF($C$6="All","*",$C$6),'Sales Data'!$D$2:$D$61,"Electronics",'Sales Data'!$L$2:$L$61,IF($C$8="All","*",$C$8)),0) -> 583423
I28: Furniture | J28: =IFERROR(SUMIFS('Sales Data'!$H$2:$H$61,'Sales Data'!$C$2:$C$61,IF($C$6="All","*",$C$6),'Sales Data'!$D$2:$D$61,"Furniture",'Sales Data'!$L$2:$L$61,IF($C$8="All","*",$C$8)),0) -> 784208
I29: Apparel | J29: =IFERROR(SUMIFS('Sales Data'!$H$2:$H$61,'Sales Data'!$C$2:$C$61,IF($C$6="All","*",$C$6),'Sales Data'!$D$2:$D$61,"Apparel",'Sales Data'!$L$2:$L$61,IF($C$8="All","*",$C$8)),0) -> 294600
I30: Groceries | J30: =IFERROR(SUMIFS('Sales Data'!$H$2:$H$61,'Sales Data'!$C$2:$C$61,IF($C$6="All","*",$C$6),'Sales Data'!$D$2:$D$61,"Groceries",'Sales Data'!$L$2:$L$61,IF($C$8="All","*",$C$8)),0) -> 76537
I32: Product | J32: Revenue
I33: Wireless Earbuds | J33: =IFERROR(SUMIFS('Sales Data'!$H$2:$H$61,'Sales Data'!$C$2:$C$61,IF($C$6="All","*",$C$6),'Sales Data'!$D$2:$D$61,IF($C$7="All","*",$C$7),'Sales Data'!$L$2:$L$61,IF($C$8="All","*",$C$8),'Sales Data'!$E$2:$E$61,"Wireless Earbuds"),0) -> 68954
I34: Smart Watch | J34: =IFERROR(SUMIFS('Sales Data'!$H$2:$H$61,'Sales Data'!$C$2:$C$61,IF($C$6="All","*",$C$6),'Sales Data'!$D$2:$D$61,IF($C$7="All","*",$C$7),'Sales Data'!$L$2:$L$61,IF($C$8="All","*",$C$8),'Sales Data'!$E$2:$E$61,"Smart Watch"),0) -> 374393
I35: Bluetooth Speaker | J35: =IFERROR(SUMIFS('Sales Data'!$H$2:$H$61,'Sales Data'!$C$2:$C$61,IF($C$6="All","*",$C$6),'Sales Data'!$D$2:$D$61,IF($C$7="All","*",$C$7),'Sales Data'!$L$2:$L$61,IF($C$8="All","*",$C$8),'Sales Data'!$E$2:$E$61,"Bluetooth Speaker"),0) -> 51974
I36: Laptop Stand | J36: =IFERROR(SUMIFS('Sales Data'!$H$2:$H$61,'Sales Data'!$C$2:$C$61,IF($C$6="All","*",$C$6),'Sales Data'!$D$2:$D$61,IF($C$7="All","*",$C$7),'Sales Data'!$L$2:$L$61,IF($C$8="All","*",$C$8),'Sales Data'!$E$2:$E$61,"Laptop Stand"),0) -> 88102
I37: Office Chair | J37: =IFERROR(SUMIFS('Sales Data'!$H$2:$H$61,'Sales Data'!$C$2:$C$61,IF($C$6="All","*",$C$6),'Sales Data'!$D$2:$D$61,IF($C$7="All","*",$C$7),'Sales Data'!$L$2:$L$61,IF($C$8="All","*",$C$8),'Sales Data'!$E$2:$E$61,"Office Chair"),0) -> 324950
I38: Study Desk | J38: =IFERROR(SUMIFS('Sales Data'!$H$2:$H$61,'Sales Data'!$C$2:$C$61,IF($C$6="All","*",$C$6),'Sales Data'!$D$2:$D$61,IF($C$7="All","*",$C$7),'Sales Data'!$L$2:$L$61,IF($C$8="All","*",$C$8),'Sales Data'!$E$2:$E$61,"Study Desk"),0) -> 263956
I39: Bookshelf | J39: =IFERROR(SUMIFS('Sales Data'!$H$2:$H$61,'Sales Data'!$C$2:$C$61,IF($C$6="All","*",$C$6),'Sales Data'!$D$2:$D$61,IF($C$7="All","*",$C$7),'Sales Data'!$L$2:$L$61,IF($C$8="All","*",$C$8),'Sales Data'!$E$2:$E$61,"Bookshelf"),0) -> 112166
I40: Sofa Cover | J40: =IFERROR(SUMIFS('Sales Data'!$H$2:$H$61,'Sales Data'!$C$2:$C$61,IF($C$6="All","*",$C$6),'Sales Data'!$D$2:$D$61,IF($C$7="All","*",$C$7),'Sales Data'!$L$2:$L$61,IF($C$8="All","*",$C$8),'Sales Data'!$E$2:$E$61,"Sofa Cover"),0) -> 83136
I41: Cotton T-Shirt | J41: =IFERROR(SUMIFS('Sales Data'!$H$2:$H$61,'Sales Data'!$C$2:$C$61,IF($C$6="All","*",$C$6),'Sales Data'!$D$2:$D$61,IF($C$7="All","*",$C$7),'Sales Data'!$L$2:$L$61,IF($C$8="All","*",$C$8),'Sales Data'!$E$2:$E$61,"Cotton T-Shirt"),0) -> 41930
I42: Denim Jacket | J42: =IFERROR(SUMIFS('Sales Data'!$H$2:$H$61,'Sales Data'!$C$2:$C$61,IF($C$6="All","*",$C$6),'Sales Data'!$D$2:$D$61,IF($C$7="All","*",$C$7),'Sales Data'!$L$2:$L$61,IF($C$8="All","*",$C$8),'Sales Data'!$E$2:$E$61,"Denim Jacket"),0) -> 123144
I43: Running Shoes | J43: =IFERROR(SUMIFS('Sales Data'!$H$2:$H$61,'Sales Data'!$C$2:$C$61,IF($C$6="All","*",$C$6),'Sales Data'!$D$2:$D$61,IF($C$7="All","*",$C$7),'Sales Data'!$L$2:$L$61,IF($C$8="All","*",$C$8),'Sales Data'!$E$2:$E$61,"Running Shoes"),0) -> 23992
I44: Winter Hoodie | J44: =IFERROR(SUMIFS('Sales Data'!$H$2:$H$61,'Sales Data'!$C$2:$C$61,IF($C$6="All","*",$C$6),'Sales Data'!$D$2:$D$61,IF($C$7="All","*",$C$7),'Sales Data'!$L$2:$L$61,IF($C$8="All","*",$C$8),'Sales Data'!$E$2:$E$61,"Winter Hoodie"),0) -> 105534
...

Sheet Sales Data
A1: Order ID | B1: Date | C1: Region | D1: Category | E1: Product | F1: Units Sold | G1: Unit Price | H1: Revenue | I1: Cost | J1: Profit | K1: Margin % | L1: Month
A2: 1001 | B2: 45672 | C2: East | D2: Electronics | E2: Smart Watch | F2: 24 | G2: 3499 | H2: 83976 | I2: 47016 | J2: 36960 | K2: =IFERROR(J2/H2,0) -> 0.44012575 | L2: =TEXT(B2,"mmm") -> Jan
A3: 1002 | B3: 45671 | C3: East | D3: Apparel | E3: Denim Jacket | F3: 8 | G3: 2199 | H3: 17592 | I3: 9848 | J3: 7744 | K3: =IFERROR(J3/H3,0) -> 0.44020009 | L3: =TEXT(B3,"mmm") -> Jan
A4: 1003 | B4: 45682 | C4: East | D4: Electronics | E4: Wireless Earbuds | F4: 14 | G4: 1499 | H4: 20986 | I4: 14266 | J4: 6720 | K4: =IFERROR(J4/H4,0) -> 0.32021348 | L4: =TEXT(B4,"mmm") -> Jan
A5: 1004 | B5: 45661 | C5: East | D5: Apparel | E5: Running Shoes | F5: 3 | G5: 2999 | H5: 8997 | I5: 5307 | J5: 3690 | K5: =IFERROR(J5/H5,0) -> 0.41013671 | L5: =TEXT(B5,"mmm") -> Jan
A6: 1005 | B6: 45703 | C6: North | D6: Groceries | E6: Organic Almonds | F6: 19 | G6: 449 | H6: 8531 | I6: 4769 | J6: 3762 | K6: =IFERROR(J6/H6,0) -> 0.44097996 | L6: =TEXT(B6,"mmm") -> Feb
A7: 1006 | B7: 45698 | C7: East | D7: Furniture | E7: Office Chair | F7: 3 | G7: 6499 | H7: 19497 | I7: 13647 | J7: 5850 | K7: =IFERROR(J7/H7,0) -> 0.30004616 | L7: =TEXT(B7,"mmm") -> Feb
A8: 1007 | B8: 45710 | C8: South | D8: Apparel | E8: Cotton T-Shirt | F8: 9 | G8: 599 | H8: 5391 | I8: 3393 | J8: 1998 | K8: =IFERROR(J8/H8,0) -> 0.3706177 | L8: =TEXT(B8,"mmm") -> Feb
A9: 1008 | B9: 45716 | C9: North | D9: Groceries | E9: Olive Oil 1L | F9: 16 | G9: 699 | H9: 11184 | I9: 7600 | J9: 3584 | K9: =IFERROR(J9/H9,0) -> 0.3204578 | L9: =TEXT(B9,"mmm") -> Feb
A10: 1009 | B10: 45709 | C10: East | D10: Furniture | E10: Bookshelf | F10: 13 | G10: 3299 | H10: 42887 | I10: 31304 | J10: 11583 | K10: =IFERROR(J10/H10,0) -> 0.27008184 | L10: =TEXT(B10,"mmm") -> Feb
A11: 1010 | B11: 45695 | C11: East | D11: Electronics | E11: Smart Watch | F11: 19 | G11: 3499 | H11: 66481 | I11: 37221 | J11: 29260 | K11: =IFERROR(J11/H11,0) -> 0.44012575 | L11: =TEXT(B11,"mmm") -> Feb
A12: 1011 | B12: 45724 | C12: South | D12: Groceries | E12: Basmati Rice 5kg | F12: 10 | G12: 599 | H12: 5990 | I12: 3950 | J12: 2040 | K12: =IFERROR(J12/H12,0) -> 0.34056761 | L12: =TEXT(B12,"mmm") -> Mar
A13: 1012 | B13: 45737 | C13: South | D13: Apparel | E13: Cotton T-Shirt | F13: 9 | G13: 599 | H13: 5391 | I13: 3393 | J13: 1998 | K13: =IFERROR(J13/H13,0) -> 0.3706177 | L13: =TEXT(B13,"mmm") -> Mar
... A61: 1060 | B61: 46014 | C61: East | D61: Electronics | E61: Bluetooth Speaker | F61: 23 | G61: 1999 | H61: 45977 | I61: 28037 | J61: 17940 | K61: =IFERROR(J61/H61,0) -> 0.3901951 | L61: =TEXT(B61,"mmm") -> Dec

Sheet Product Lookup
A1: Product ID | B1: Product Name | C1: Category | D1: Unit Price | E1: Unit Cost | F1: Margin % | H1: Product Lookup Tool
A2: P001 | B2: Wireless Earbuds | C2: Electronics | D2: 1499 | E2: 1019 | F2: =IFERROR((D2-E2)/D2,0) -> 0.32021348
A3: P002 | B3: Smart Watch | C3: Electronics | D3: 3499 | E3: 1959 | F3: =IFERROR((D3-E3)/D3,0) -> 0.44012575 | H3: Enter Product ID: | I3: P008
A4: P003 | B4: Bluetooth Speaker | C4: Electronics | D4: 1999 | E4: 1219 | F4: =IFERROR((D4-E4)/D4,0) -> 0.3901951
A5: P004 | B5: Laptop Stand | C5: Electronics | D5: 899 | E5: 530 | F5: =IFERROR((D5-E5)/D5,0) -> 0.41045606 | H5: Product Name | I5: =IFERROR(INDEX($B$2:$B$17,MATCH($I$3,$A$2:$A$17,0)),"Not found") -> Sofa Cover
A6: P005 | B6: Office Chair | C6: Furniture | D6: 6499 | E6: 4549 | F6: =IFERROR((D6-E6)/D6,0) -> 0.30004616 | H6: Category | I6: =IFERROR(INDEX($C$2:$C$17,MATCH($I$3,$A$2:$A$17,0)),"Not found") -> Furniture
A7: P006 | B7: Study Desk | C7: Furniture | D7: 5999 | E7: 4139 | F7: =IFERROR((D7-E7)/D7,0) -> 0.31005168 | H7: Unit Price | I7: =IFERROR(INDEX($D$2:$D$17,MATCH($I$3,$A$2:$A$17,0)),"Not found") -> 1299
A8: P007 | B8: Bookshelf | C8: Furniture | D8: 3299 | E8: 2408 | F8: =IFERROR((D8-E8)/D8,0) -> 0.27008184 | H8: Unit Cost | I8: =IFERROR(INDEX($E$2:$E$17,MATCH($I$3,$A$2:$A$17,0)),"Not found") -> 740
A9: P008 | B9: Sofa Cover | C9: Furniture | D9: 1299 | E9: 740 | F9: =IFERROR((D9-E9)/D9,0) -> 0.43033102 | H9: Margin % | I9: =IFERROR(INDEX($F$2:$F$17,MATCH($I$3,$A$2:$A$17,0)),"Not found") -> 0.43033102
A10: P009 | B10: Cotton T-Shirt | C10: Apparel | D10: 599 | E10: 377 | F10: =IFERROR((D10-E10)/D10,0) -> 0.3706177
A11: P010 | B11: Denim Jacket | C11: Apparel | D11: 2199 | E11: 1231 | F11: =IFERROR((D11-E11)/D11,0) -> 0.44020009
A12: P011 | B12: Running Shoes | C12: Apparel | D12: 2999 | E12: 1769 | F12: =IFERROR((D12-E12)/D12,0) -> 0.41013671
A13: P012 | B13: Winter Hoodie | C13: Apparel | D13: 1599 | E13: 1039 | F13: =IFERROR((D13-E13)/D13,0) -> 0.35021889
A14: P013 | B14: Organic Almonds | C14: Groceries | D14: 449 | E14: 251 | F14: =IFERROR((D14-E14)/D14,0) -> 0.44097996
A15: P014 | B15: Green Tea Pack | C15: Groceries | D15: 299 | E15: 176 | F15: =IFERROR((D15-E15)/D15,0) -> 0.41137124
A16: P015 | B16: Olive Oil 1L | C16: Groceries | D16: 699 | E16: 475 | F16: =IFERROR((D16-E16)/D16,0) -> 0.3204578
A17: P016 | B17: Basmati Rice 5kg | C17: Groceries | D17: 599 | E17: 395 | F17: =IFERROR((D17-E17)/D17,0) -> 0.34056761
